[33mWARNING [0m juju.client.connection:connection.py:493 Receiver: Connection closed, reconnecting
[33mWARNING [0m juju.client.connection:connection.py:493 Receiver: Connection closed, reconnecting
[33mWARNING [0m juju.client.connection:connection.py:493 Receiver: Connection closed, reconnecting
[1m[31mERROR   [0m asyncio:base_events.py:1821 Task exception was never retrieved
future: <Task finished name='Task-1394' coro=<Connection.reconnect() done, defined at /home/ubuntu/actions-runner/_work/jenkins-k8s-operator/jenkins-k8s-operator/.tox/integration/lib/python3.12/site-packages/juju/client/connection.py:697> exception=ProxyNotConnectedError()>
Traceback (most recent call last):
  File "/home/ubuntu/actions-runner/_work/jenkins-k8s-operator/jenkins-k8s-operator/.tox/integration/lib/python3.12/site-packages/juju/client/connection.py", line 709, in reconnect
    res = await connector(
          ^^^^^^^^^^^^^^^^
  File "/home/ubuntu/actions-runner/_work/jenkins-k8s-operator/jenkins-k8s-operator/.tox/integration/lib/python3.12/site-packages/juju/client/connection.py", line 800, in _connect_with_login
    await self._connect(endpoints)
  File "/home/ubuntu/actions-runner/_work/jenkins-k8s-operator/jenkins-k8s-operator/.tox/integration/lib/python3.12/site-packages/juju/client/connection.py", line 743, in _connect
    result = await task
             ^^^^^^^^^^
  File "/usr/lib/python3.12/asyncio/tasks.py", line 631, in _wait_for_one
    return f.result()  # May raise f.exception().
           ^^^^^^^^^^
  File "/home/ubuntu/actions-runner/_work/jenkins-k8s-operator/jenkins-k8s-operator/.tox/integration/lib/python3.12/site-packages/juju/client/connection.py", line 729, in _try_endpoint
    return await self._open(endpoint, cacert)
           ^^^^^^^^^^^^^^^^^^^^^^^^^^^^^^^^^^
  File "/home/ubuntu/actions-runner/_work/jenkins-k8s-operator/jenkins-k8s-operator/.tox/integration/lib/python3.12/site-packages/juju/client/connection.py", line 328, in _open
    sock = self.proxy.socket()
           ^^^^^^^^^^^^^^^^^^^
  File "/home/ubuntu/actions-runner/_work/jenkins-k8s-operator/jenkins-k8s-operator/.tox/integration/lib/python3.12/site-packages/juju/client/proxy/kubernetes/proxy.py", line 80, in socket
    raise ProxyNotConnectedError()
juju.client.proxy.proxy.ProxyNotConnectedError
[1m[31mERROR   [0m asyncio:base_events.py:1821 Task exception was never retrieved
future: <Task finished name='Task-1396' coro=<Connection.reconnect() done, defined at /home/ubuntu/actions-runner/_work/jenkins-k8s-operator/jenkins-k8s-operator/.tox/integration/lib/python3.12/site-packages/juju/client/connection.py:697> exception=ProxyNotConnectedError()>
Traceback (most recent call last):
  File "/home/ubuntu/actions-runner/_work/jenkins-k8s-operator/jenkins-k8s-operator/.tox/integration/lib/python3.12/site-packages/juju/client/connection.py", line 709, in reconnect
    res = await connector(
          ^^^^^^^^^^^^^^^^
  File "/home/ubuntu/actions-runner/_work/jenkins-k8s-operator/jenkins-k8s-operator/.tox/integration/lib/python3.12/site-packages/juju/client/connection.py", line 800, in _connect_with_login
    await self._connect(endpoints)
  File "/home/ubuntu/actions-runner/_work/jenkins-k8s-operator/jenkins-k8s-operator/.tox/integration/lib/python3.12/site-packages/juju/client/connection.py", line 743, in _connect
    result = await task
             ^^^^^^^^^^
  File "/usr/lib/python3.12/asyncio/tasks.py", line 631, in _wait_for_one
    return f.result()  # May raise f.exception().
           ^^^^^^^^^^
  File "/home/ubuntu/actions-runner/_work/jenkins-k8s-operator/jenkins-k8s-operator/.tox/integration/lib/python3.12/site-packages/juju/client/connection.py", line 729, in _try_endpoint
    return await self._open(endpoint, cacert)
           ^^^^^^^^^^^^^^^^^^^^^^^^^^^^^^^^^^
  File "/home/ubuntu/actions-runner/_work/jenkins-k8s-operator/jenkins-k8s-operator/.tox/integration/lib/python3.12/site-packages/juju/client/connection.py", line 328, in _open
    sock = self.proxy.socket()
           ^^^^^^^^^^^^^^^^^^^
  File "/home/ubuntu/actions-runner/_work/jenkins-k8s-operator/jenkins-k8s-operator/.tox/integration/lib/python3.12/site-packages/juju/client/proxy/kubernetes/proxy.py", line 80, in socket
    raise ProxyNotConnectedError()
juju.client.proxy.proxy.ProxyNotConnectedError
[1m[31mERROR   [0m asyncio:base_events.py:1821 Task exception was never retrieved
future: <Task finished name='Task-1397' coro=<Connection.reconnect() done, defined at /home/ubuntu/actions-runner/_work/jenkins-k8s-operator/jenkins-k8s-operator/.tox/integration/lib/python3.12/site-packages/juju/client/connection.py:697> exception=ProxyNotConnectedError()>
Traceback (most recent call last):
  File "/home/ubuntu/actions-runner/_work/jenkins-k8s-operator/jenkins-k8s-operator/.tox/integration/lib/python3.12/site-packages/juju/client/connection.py", line 709, in reconnect
    res = await connector(
          ^^^^^^^^^^^^^^^^
  File "/home/ubuntu/actions-runner/_work/jenkins-k8s-operator/jenkins-k8s-operator/.tox/integration/lib/python3.12/site-packages/juju/client/connection.py", line 800, in _connect_with_login
    await self._connect(endpoints)
  File "/home/ubuntu/actions-runner/_work/jenkins-k8s-operator/jenkins-k8s-operator/.tox/integration/lib/python3.12/site-packages/juju/client/connection.py", line 743, in _connect
    result = await task
             ^^^^^^^^^^
  File "/usr/lib/python3.12/asyncio/tasks.py", line 631, in _wait_for_one
    return f.result()  # May raise f.exception().
           ^^^^^^^^^^
  File "/home/ubuntu/actions-runner/_work/jenkins-k8s-operator/jenkins-k8s-operator/.tox/integration/lib/python3.12/site-packages/juju/client/connection.py", line 729, in _try_endpoint
    return await self._open(endpoint, cacert)
           ^^^^^^^^^^^^^^^^^^^^^^^^^^^^^^^^^^
  File "/home/ubuntu/actions-runner/_work/jenkins-k8s-operator/jenkins-k8s-operator/.tox/integration/lib/python3.12/site-packages/juju/client/connection.py", line 328, in _open
    sock = self.proxy.socket()
           ^^^^^^^^^^^^^^^^^^^
  File "/home/ubuntu/actions-runner/_work/jenkins-k8s-operator/jenkins-k8s-operator/.tox/integration/lib/python3.12/site-packages/juju/client/proxy/kubernetes/proxy.py", line 80, in socket
    raise ProxyNotConnectedError()
juju.client.proxy.proxy.ProxyNotConnectedError
[1m[31mERROR   [0m jenkinsapi.jenkinsbase:jenkinsbase.py:85 Failed request at http://10.1.53.14:8080/api/python with params: {'tree': 'jobs[name,color,url]'} jobs[name,color,url]
[1m[31mERROR   [0m jenkinsapi.jenkinsbase:jenkinsbase.py:85 Failed request at http://10.1.53.14:8080/api/python with params: {'tree': 'jobs[name,color,url]'} jobs[name,color,url]
[32mINFO    [0m jenkinsapi.build:build.py:399 Waited 0s for pipeline_model_definition_plugin_test #pipeline_model_definition_plugin_test #1 to complete
[32mINFO    [0m pytest_operator.plugin:plugin.py:951 Model status:

Model    Controller                Cloud/Region        Version  SLA          Timestamp
testing  github-pr-1ed91-microk8s  microk8s/localhost  3.6.11   unsupported  10:51:02Z

App                Version  Status  Scale  Charm              Channel      Rev  Address         Exposed  Message
jenkins-agent-k8s           active      1  jenkins-agent-k8s  latest/edge   41  10.152.183.224  no       
jenkins-k8s        2.528.1  active      1  jenkins-k8s                       0  10.152.183.31   no       

Unit                  Workload  Agent  Address     Ports  Message
jenkins-agent-k8s/0*  active    idle   10.1.53.15         
jenkins-k8s/0*        active    idle   10.1.53.14         

[32mINFO    [0m pytest_operator.plugin:plugin.py:957 Juju error logs:


[32mINFO    [0m pytest_operator.plugin:plugin.py:1039 Forgetting model main...